<?xml version="1.0" ?>
<robot name="my_robot">
    <link name="base_link">
    <visual>
        <origin xyz="0 0 0" rpy="0 0 0"/>
        <geometry>
        <box size="0.5 0.35 0.28"/>
        </geometry>
        <material name="blue">
        <color rgba="0 0 1 1"/>
        </material>
    </visual>
    </link>

    <link name="left_front_wheel_link">
        <visual>
            <origin xyz="0 0 0" rpy="1.5707 0 0" />
            <geometry>
                <cylinder radius="0.06" length = "0.08"/>
            </geometry>
            <material name="white">
                <color rgba="1 1 1 0.9"/>
            </material>
        </visual>
    </link>

    <joint name="left_front_wheel_joint" type="continuous">
        <origin xyz="-0.15 0.175 -0.15" rpy="0 0 0"/>
        <parent link="base_link"/>
        <child link="left_front_wheel_link"/>
        <axis xyz="0 1 0"/>
    </joint>

    <link name="left_back_wheel_link">
        <visual>
            <origin xyz="0 0 0" rpy="1.5707 0 0" />
            <geometry>
                <cylinder radius="0.06" length = "0.08"/>
            </geometry>
            <material name="white">
                <color rgba="1 1 1 0.9"/>
            </material>
        </visual>
    </link>

    <joint name="left_back_wheel_joint" type="continuous">
        <origin xyz="0.15 0.175 -0.15" rpy="0 0 0"/>
        <parent link="base_link"/>
        <child link="left_back_wheel_link"/>
        <axis xyz="0 1 0"/>
    </joint>

    <link name="right_front_wheel_link">
        <visual>
            <origin xyz="0 0 0" rpy="1.5707 0 0" />
            <geometry>
                <cylinder radius="0.06" length = "0.08"/>
            </geometry>
            <material name="white">
                <color rgba="1 1 1 0.9"/>
            </material>
        </visual>
    </link>

    <joint name="right_front_wheel_joint" type="continuous">
        <origin xyz="-0.15 -0.175 -0.15" rpy="0 0 0"/>
        <parent link="base_link"/>
        <child link="right_front_wheel_link"/>
        <axis xyz="0 1 0"/>
    </joint>

    <link name="right_back_wheel_link">
        <visual>
            <origin xyz="0 0 0" rpy="1.5707 0 0" />
            <geometry>
                <cylinder radius="0.06" length = "0.08"/>
            </geometry>
            <material name="white">
                <color rgba="1 1 1 0.9"/>
            </material>
        </visual>
    </link>

    <joint name="right_back_wheel_joint" type="continuous">
        <origin xyz="0.15 -0.175 -0.15" rpy="0 0 0"/>
        <parent link="base_link"/>
        <child link="right_back_wheel_link"/>
        <axis xyz="0 1 0"/>
    </joint>

</robot>